{
 "cells": [
  {
   "cell_type": "code",
   "execution_count": 22,
   "id": "4a6acc55-c929-47b3-934c-df2b7cd1e236",
   "metadata": {},
   "outputs": [],
   "source": [
    "from models.database import init_db"
   ]
  },
  {
   "cell_type": "code",
   "execution_count": 23,
   "id": "65767098-9cf0-4122-a924-50041b4ade1c",
   "metadata": {},
   "outputs": [],
   "source": [
    "init_db()"
   ]
  },
  {
   "cell_type": "code",
   "execution_count": 24,
   "id": "7e8a136c-94f1-4e33-8c3c-21fe5d48177f",
   "metadata": {},
   "outputs": [
    {
     "name": "stdout",
     "output_type": "stream",
     "text": [
      " * Serving Flask app 'app.my_app' (lazy loading)\n",
      " * Environment: production\n",
      "\u001b[31m   WARNING: This is a development server. Do not use it in a production deployment.\u001b[0m\n",
      "\u001b[2m   Use a production WSGI server instead.\u001b[0m\n",
      " * Debug mode: on\n",
      " * Running on all addresses.\n",
      "   WARNING: This is a development server. Do not use it in a production deployment.\n",
      " * Running on http://192.168.101.7:8000/ (Press CTRL+C to quit)\n",
      " * Restarting with stat\n",
      " * Debugger is active!\n",
      " * Debugger PIN: 324-868-349\n",
      "192.168.100.20 - - [31/Aug/2021 13:51:19] \"GET /task/hypara_test HTTP/1.1\" 200 -\n",
      "192.168.100.20 - - [31/Aug/2021 13:51:19] \"GET /static/css/bootstrap.min.css HTTP/1.1\" 200 -\n",
      "192.168.100.20 - - [31/Aug/2021 13:51:19] \"GET /static/js/bootstrap.min.js HTTP/1.1\" 200 -\n",
      "192.168.100.20 - - [31/Aug/2021 13:51:19] \"GET /templates/purple.png HTTP/1.1\" 200 -\n",
      "192.168.100.20 - - [31/Aug/2021 13:51:19] \"GET /templates/yakan.png HTTP/1.1\" 200 -\n",
      "192.168.100.20 - - [31/Aug/2021 13:51:19] \"GET /templates/yellow.png HTTP/1.1\" 200 -\n",
      "192.168.100.20 - - [31/Aug/2021 13:51:20] \"\u001b[33mGET /favicon.ico HTTP/1.1\u001b[0m\" 404 -\n",
      "192.168.100.20 - - [31/Aug/2021 13:51:28] \"\u001b[32mPOST /add HTTP/1.1\u001b[0m\" 302 -\n",
      "192.168.100.20 - - [31/Aug/2021 13:51:28] \"GET /top HTTP/1.1\" 200 -\n",
      "192.168.100.20 - - [31/Aug/2021 13:51:33] \"\u001b[32mPOST /login HTTP/1.1\u001b[0m\" 302 -\n",
      "192.168.100.20 - - [31/Aug/2021 13:51:33] \"GET /top?status=user_notfound HTTP/1.1\" 200 -\n",
      "192.168.100.20 - - [31/Aug/2021 13:51:37] \"\u001b[32mPOST /login HTTP/1.1\u001b[0m\" 302 -\n",
      "192.168.100.20 - - [31/Aug/2021 13:51:37] \"GET /top?status=user_notfound HTTP/1.1\" 200 -\n",
      "192.168.100.20 - - [31/Aug/2021 13:51:39] \"GET /newcomer HTTP/1.1\" 200 -\n",
      "192.168.100.20 - - [31/Aug/2021 13:51:42] \"\u001b[32mPOST /registar HTTP/1.1\u001b[0m\" 302 -\n",
      "192.168.100.20 - - [31/Aug/2021 13:51:42] \"GET /task/hypara_test HTTP/1.1\" 200 -\n",
      "192.168.100.20 - - [31/Aug/2021 13:51:42] \"\u001b[36mGET /static/js/bootstrap.min.js HTTP/1.1\u001b[0m\" 304 -\n",
      "Exception during reset or similar\n",
      "Traceback (most recent call last):\n",
      "  File \"/opt/conda/lib/python3.8/site-packages/sqlalchemy/pool/base.py\", line 682, in _finalize_fairy\n",
      "    fairy._reset(pool)\n",
      "  File \"/opt/conda/lib/python3.8/site-packages/sqlalchemy/pool/base.py\", line 887, in _reset\n",
      "    pool._dialect.do_rollback(self)\n",
      "  File \"/opt/conda/lib/python3.8/site-packages/sqlalchemy/engine/default.py\", line 667, in do_rollback\n",
      "    dbapi_connection.rollback()\n",
      "sqlite3.ProgrammingError: SQLite objects created in a thread can only be used in that same thread. The object was created in thread id 140094098577152 and this is thread id 140094090184448.\n",
      "Exception closing connection <sqlite3.Connection object at 0x7f6a342ff8a0>\n",
      "Traceback (most recent call last):\n",
      "  File \"/opt/conda/lib/python3.8/site-packages/sqlalchemy/pool/base.py\", line 682, in _finalize_fairy\n",
      "    fairy._reset(pool)\n",
      "  File \"/opt/conda/lib/python3.8/site-packages/sqlalchemy/pool/base.py\", line 887, in _reset\n",
      "    pool._dialect.do_rollback(self)\n",
      "  File \"/opt/conda/lib/python3.8/site-packages/sqlalchemy/engine/default.py\", line 667, in do_rollback\n",
      "    dbapi_connection.rollback()\n",
      "sqlite3.ProgrammingError: SQLite objects created in a thread can only be used in that same thread. The object was created in thread id 140094098577152 and this is thread id 140094090184448.\n",
      "\n",
      "During handling of the above exception, another exception occurred:\n",
      "\n",
      "Traceback (most recent call last):\n",
      "  File \"/opt/conda/lib/python3.8/site-packages/sqlalchemy/pool/base.py\", line 244, in _close_connection\n",
      "    self._dialect.do_close(connection)\n",
      "  File \"/opt/conda/lib/python3.8/site-packages/sqlalchemy/engine/default.py\", line 673, in do_close\n",
      "    dbapi_connection.close()\n",
      "sqlite3.ProgrammingError: SQLite objects created in a thread can only be used in that same thread. The object was created in thread id 140094098577152 and this is thread id 140094090184448.\n",
      "192.168.100.20 - - [31/Aug/2021 13:51:42] \"\u001b[36mGET /static/css/bootstrap.min.css HTTP/1.1\u001b[0m\" 304 -\n",
      "192.168.100.20 - - [31/Aug/2021 13:51:42] \"\u001b[36mGET /templates/purple.png HTTP/1.1\u001b[0m\" 304 -\n",
      "192.168.100.20 - - [31/Aug/2021 13:51:42] \"GET /templates/cat.png HTTP/1.1\" 200 -\n",
      "192.168.100.20 - - [31/Aug/2021 13:51:42] \"GET /templates/white.png HTTP/1.1\" 200 -\n",
      "192.168.100.20 - - [31/Aug/2021 13:51:52] \"\u001b[32mPOST /add HTTP/1.1\u001b[0m\" 302 -\n",
      "192.168.100.20 - - [31/Aug/2021 13:51:52] \"GET /task/hypara_test HTTP/1.1\" 200 -\n",
      "192.168.100.20 - - [31/Aug/2021 13:51:52] \"\u001b[36mGET /static/css/bootstrap.min.css HTTP/1.1\u001b[0m\" 304 -\n",
      "192.168.100.20 - - [31/Aug/2021 13:51:52] \"\u001b[36mGET /static/js/bootstrap.min.js HTTP/1.1\u001b[0m\" 304 -\n",
      "192.168.100.20 - - [31/Aug/2021 13:51:53] \"GET /templates/bluepurple.png HTTP/1.1\" 200 -\n",
      "192.168.100.20 - - [31/Aug/2021 13:51:53] \"\u001b[36mGET /templates/yakan.png HTTP/1.1\u001b[0m\" 304 -\n",
      "192.168.100.20 - - [31/Aug/2021 13:51:53] \"GET /templates/yellowred.png HTTP/1.1\" 200 -\n",
      "Exception during reset or similar\n",
      "Traceback (most recent call last):\n",
      "  File \"/opt/conda/lib/python3.8/site-packages/sqlalchemy/pool/base.py\", line 682, in _finalize_fairy\n",
      "    fairy._reset(pool)\n",
      "  File \"/opt/conda/lib/python3.8/site-packages/sqlalchemy/pool/base.py\", line 887, in _reset\n",
      "    pool._dialect.do_rollback(self)\n",
      "  File \"/opt/conda/lib/python3.8/site-packages/sqlalchemy/engine/default.py\", line 667, in do_rollback\n",
      "    dbapi_connection.rollback()\n",
      "sqlite3.ProgrammingError: SQLite objects created in a thread can only be used in that same thread. The object was created in thread id 140094090184448 and this is thread id 140094098577152.\n",
      "Exception closing connection <sqlite3.Connection object at 0x7f6a342ff8a0>\n",
      "Traceback (most recent call last):\n",
      "  File \"/opt/conda/lib/python3.8/site-packages/sqlalchemy/pool/base.py\", line 682, in _finalize_fairy\n",
      "    fairy._reset(pool)\n",
      "  File \"/opt/conda/lib/python3.8/site-packages/sqlalchemy/pool/base.py\", line 887, in _reset\n",
      "    pool._dialect.do_rollback(self)\n",
      "  File \"/opt/conda/lib/python3.8/site-packages/sqlalchemy/engine/default.py\", line 667, in do_rollback\n",
      "    dbapi_connection.rollback()\n",
      "sqlite3.ProgrammingError: SQLite objects created in a thread can only be used in that same thread. The object was created in thread id 140094090184448 and this is thread id 140094098577152.\n",
      "\n",
      "During handling of the above exception, another exception occurred:\n",
      "\n",
      "Traceback (most recent call last):\n",
      "  File \"/opt/conda/lib/python3.8/site-packages/sqlalchemy/pool/base.py\", line 244, in _close_connection\n",
      "    self._dialect.do_close(connection)\n",
      "  File \"/opt/conda/lib/python3.8/site-packages/sqlalchemy/engine/default.py\", line 673, in do_close\n",
      "    dbapi_connection.close()\n",
      "sqlite3.ProgrammingError: SQLite objects created in a thread can only be used in that same thread. The object was created in thread id 140094090184448 and this is thread id 140094098577152.\n",
      "192.168.100.20 - - [31/Aug/2021 13:51:59] \"\u001b[32mPOST /add HTTP/1.1\u001b[0m\" 302 -\n",
      "192.168.100.20 - - [31/Aug/2021 13:51:59] \"GET /task/hypara_test HTTP/1.1\" 200 -\n",
      "192.168.100.20 - - [31/Aug/2021 13:51:59] \"\u001b[36mGET /static/css/bootstrap.min.css HTTP/1.1\u001b[0m\" 304 -\n",
      "192.168.100.20 - - [31/Aug/2021 13:51:59] \"\u001b[36mGET /static/js/bootstrap.min.js HTTP/1.1\u001b[0m\" 304 -\n",
      "192.168.100.20 - - [31/Aug/2021 13:51:59] \"\u001b[36mGET /templates/bluepurple.png HTTP/1.1\u001b[0m\" 304 -\n",
      "192.168.100.20 - - [31/Aug/2021 13:51:59] \"GET /templates/dog.png HTTP/1.1\" 200 -\n",
      "192.168.100.20 - - [31/Aug/2021 13:51:59] \"\u001b[36mGET /templates/yellowred.png HTTP/1.1\u001b[0m\" 304 -\n",
      "192.168.100.20 - - [31/Aug/2021 13:52:05] \"\u001b[32mPOST /add HTTP/1.1\u001b[0m\" 302 -\n",
      "192.168.100.20 - - [31/Aug/2021 13:52:06] \"GET /task/hypara_test HTTP/1.1\" 200 -\n",
      "192.168.100.20 - - [31/Aug/2021 13:52:06] \"\u001b[36mGET /static/css/bootstrap.min.css HTTP/1.1\u001b[0m\" 304 -\n",
      "192.168.100.20 - - [31/Aug/2021 13:52:06] \"\u001b[36mGET /static/js/bootstrap.min.js HTTP/1.1\u001b[0m\" 304 -\n",
      "192.168.100.20 - - [31/Aug/2021 13:52:06] \"\u001b[36mGET /templates/dog.png HTTP/1.1\u001b[0m\" 304 -\n",
      "192.168.100.20 - - [31/Aug/2021 13:52:06] \"\u001b[36mGET /templates/yellow.png HTTP/1.1\u001b[0m\" 304 -\n",
      "192.168.100.20 - - [31/Aug/2021 13:52:06] \"GET /templates/green.png HTTP/1.1\" 200 -\n",
      "192.168.100.20 - - [31/Aug/2021 13:52:11] \"\u001b[32mPOST /add HTTP/1.1\u001b[0m\" 302 -\n",
      "192.168.100.20 - - [31/Aug/2021 13:52:11] \"GET /task/hypara_test HTTP/1.1\" 200 -\n",
      "192.168.100.20 - - [31/Aug/2021 13:52:12] \"\u001b[36mGET /static/css/bootstrap.min.css HTTP/1.1\u001b[0m\" 304 -\n",
      "192.168.100.20 - - [31/Aug/2021 13:52:12] \"\u001b[36mGET /static/js/bootstrap.min.js HTTP/1.1\u001b[0m\" 304 -\n",
      "192.168.100.20 - - [31/Aug/2021 13:52:12] \"GET /templates/kyusu.png HTTP/1.1\" 200 -\n",
      "192.168.100.20 - - [31/Aug/2021 13:52:12] \"\u001b[36mGET /templates/white.png HTTP/1.1\u001b[0m\" 304 -\n",
      "192.168.100.20 - - [31/Aug/2021 13:52:12] \"\u001b[36mGET /templates/bluepurple.png HTTP/1.1\u001b[0m\" 304 -\n",
      "192.168.100.20 - - [31/Aug/2021 13:52:13] \"\u001b[32mGET /logout HTTP/1.1\u001b[0m\" 302 -\n",
      "192.168.100.20 - - [31/Aug/2021 13:52:13] \"GET /top?status=logout HTTP/1.1\" 200 -\n",
      "^C\n",
      "Traceback (most recent call last):\n",
      "  File \"/workspace/sample/run.py\", line 1, in <module>\n",
      "    from app.my_app import my_app\n",
      "ImportError: cannot import name 'my_app' from 'app.my_app' (/workspace/sample/app/my_app.py)\n",
      "Exception during reset or similar\n",
      "Traceback (most recent call last):\n",
      "  File \"/opt/conda/lib/python3.8/site-packages/sqlalchemy/pool/base.py\", line 682, in _finalize_fairy\n",
      "    fairy._reset(pool)\n",
      "  File \"/opt/conda/lib/python3.8/site-packages/sqlalchemy/pool/base.py\", line 887, in _reset\n",
      "    pool._dialect.do_rollback(self)\n",
      "  File \"/opt/conda/lib/python3.8/site-packages/sqlalchemy/engine/default.py\", line 667, in do_rollback\n",
      "    dbapi_connection.rollback()\n",
      "sqlite3.ProgrammingError: SQLite objects created in a thread can only be used in that same thread. The object was created in thread id 140094098577152 and this is thread id 140094168958784.\n",
      "Exception closing connection <sqlite3.Connection object at 0x7f6a342ff8a0>\n",
      "Traceback (most recent call last):\n",
      "  File \"/opt/conda/lib/python3.8/site-packages/sqlalchemy/pool/base.py\", line 682, in _finalize_fairy\n",
      "    fairy._reset(pool)\n",
      "  File \"/opt/conda/lib/python3.8/site-packages/sqlalchemy/pool/base.py\", line 887, in _reset\n",
      "    pool._dialect.do_rollback(self)\n",
      "  File \"/opt/conda/lib/python3.8/site-packages/sqlalchemy/engine/default.py\", line 667, in do_rollback\n",
      "    dbapi_connection.rollback()\n",
      "sqlite3.ProgrammingError: SQLite objects created in a thread can only be used in that same thread. The object was created in thread id 140094098577152 and this is thread id 140094168958784.\n",
      "\n",
      "During handling of the above exception, another exception occurred:\n",
      "\n",
      "Traceback (most recent call last):\n",
      "  File \"/opt/conda/lib/python3.8/site-packages/sqlalchemy/pool/base.py\", line 244, in _close_connection\n",
      "    self._dialect.do_close(connection)\n",
      "  File \"/opt/conda/lib/python3.8/site-packages/sqlalchemy/engine/default.py\", line 673, in do_close\n",
      "    dbapi_connection.close()\n",
      "sqlite3.ProgrammingError: SQLite objects created in a thread can only be used in that same thread. The object was created in thread id 140094098577152 and this is thread id 140094168958784.\n",
      "Exception during reset or similar\n",
      "Traceback (most recent call last):\n",
      "  File \"/opt/conda/lib/python3.8/site-packages/sqlalchemy/pool/base.py\", line 682, in _finalize_fairy\n",
      "    fairy._reset(pool)\n",
      "  File \"/opt/conda/lib/python3.8/site-packages/sqlalchemy/pool/base.py\", line 887, in _reset\n",
      "    pool._dialect.do_rollback(self)\n",
      "  File \"/opt/conda/lib/python3.8/site-packages/sqlalchemy/engine/default.py\", line 667, in do_rollback\n",
      "    dbapi_connection.rollback()\n",
      "sqlite3.ProgrammingError: SQLite objects created in a thread can only be used in that same thread. The object was created in thread id 140094098577152 and this is thread id 140094168958784.\n",
      "Exception closing connection <sqlite3.Connection object at 0x7f6a342ffb70>\n",
      "Traceback (most recent call last):\n",
      "  File \"/opt/conda/lib/python3.8/site-packages/sqlalchemy/pool/base.py\", line 682, in _finalize_fairy\n",
      "    fairy._reset(pool)\n",
      "  File \"/opt/conda/lib/python3.8/site-packages/sqlalchemy/pool/base.py\", line 887, in _reset\n",
      "    pool._dialect.do_rollback(self)\n",
      "  File \"/opt/conda/lib/python3.8/site-packages/sqlalchemy/engine/default.py\", line 667, in do_rollback\n",
      "    dbapi_connection.rollback()\n",
      "sqlite3.ProgrammingError: SQLite objects created in a thread can only be used in that same thread. The object was created in thread id 140094098577152 and this is thread id 140094168958784.\n",
      "\n",
      "During handling of the above exception, another exception occurred:\n",
      "\n",
      "Traceback (most recent call last):\n",
      "  File \"/opt/conda/lib/python3.8/site-packages/sqlalchemy/pool/base.py\", line 244, in _close_connection\n",
      "    self._dialect.do_close(connection)\n",
      "  File \"/opt/conda/lib/python3.8/site-packages/sqlalchemy/engine/default.py\", line 673, in do_close\n",
      "    dbapi_connection.close()\n",
      "sqlite3.ProgrammingError: SQLite objects created in a thread can only be used in that same thread. The object was created in thread id 140094098577152 and this is thread id 140094168958784.\n",
      "Exception during reset or similar\n",
      "Traceback (most recent call last):\n",
      "  File \"/opt/conda/lib/python3.8/site-packages/sqlalchemy/pool/base.py\", line 682, in _finalize_fairy\n",
      "    fairy._reset(pool)\n",
      "  File \"/opt/conda/lib/python3.8/site-packages/sqlalchemy/pool/base.py\", line 887, in _reset\n",
      "    pool._dialect.do_rollback(self)\n",
      "  File \"/opt/conda/lib/python3.8/site-packages/sqlalchemy/engine/default.py\", line 667, in do_rollback\n",
      "    dbapi_connection.rollback()\n",
      "sqlite3.ProgrammingError: SQLite objects created in a thread can only be used in that same thread. The object was created in thread id 140094098577152 and this is thread id 140094168958784.\n",
      "Exception closing connection <sqlite3.Connection object at 0x7f6a342ffc60>\n",
      "Traceback (most recent call last):\n",
      "  File \"/opt/conda/lib/python3.8/site-packages/sqlalchemy/pool/base.py\", line 682, in _finalize_fairy\n",
      "    fairy._reset(pool)\n",
      "  File \"/opt/conda/lib/python3.8/site-packages/sqlalchemy/pool/base.py\", line 887, in _reset\n",
      "    pool._dialect.do_rollback(self)\n",
      "  File \"/opt/conda/lib/python3.8/site-packages/sqlalchemy/engine/default.py\", line 667, in do_rollback\n",
      "    dbapi_connection.rollback()\n",
      "sqlite3.ProgrammingError: SQLite objects created in a thread can only be used in that same thread. The object was created in thread id 140094098577152 and this is thread id 140094168958784.\n",
      "\n",
      "During handling of the above exception, another exception occurred:\n",
      "\n",
      "Traceback (most recent call last):\n",
      "  File \"/opt/conda/lib/python3.8/site-packages/sqlalchemy/pool/base.py\", line 244, in _close_connection\n",
      "    self._dialect.do_close(connection)\n",
      "  File \"/opt/conda/lib/python3.8/site-packages/sqlalchemy/engine/default.py\", line 673, in do_close\n",
      "    dbapi_connection.close()\n",
      "sqlite3.ProgrammingError: SQLite objects created in a thread can only be used in that same thread. The object was created in thread id 140094098577152 and this is thread id 140094168958784.\n",
      "Exception during reset or similar\n",
      "Traceback (most recent call last):\n",
      "  File \"/opt/conda/lib/python3.8/site-packages/sqlalchemy/pool/base.py\", line 682, in _finalize_fairy\n",
      "    fairy._reset(pool)\n",
      "  File \"/opt/conda/lib/python3.8/site-packages/sqlalchemy/pool/base.py\", line 887, in _reset\n",
      "    pool._dialect.do_rollback(self)\n",
      "  File \"/opt/conda/lib/python3.8/site-packages/sqlalchemy/engine/default.py\", line 667, in do_rollback\n",
      "    dbapi_connection.rollback()\n",
      "sqlite3.ProgrammingError: SQLite objects created in a thread can only be used in that same thread. The object was created in thread id 140094090184448 and this is thread id 140094168958784.\n",
      "Exception closing connection <sqlite3.Connection object at 0x7f6a342ffa80>\n",
      "Traceback (most recent call last):\n",
      "  File \"/opt/conda/lib/python3.8/site-packages/sqlalchemy/pool/base.py\", line 682, in _finalize_fairy\n",
      "    fairy._reset(pool)\n",
      "  File \"/opt/conda/lib/python3.8/site-packages/sqlalchemy/pool/base.py\", line 887, in _reset\n",
      "    pool._dialect.do_rollback(self)\n",
      "  File \"/opt/conda/lib/python3.8/site-packages/sqlalchemy/engine/default.py\", line 667, in do_rollback\n",
      "    dbapi_connection.rollback()\n",
      "sqlite3.ProgrammingError: SQLite objects created in a thread can only be used in that same thread. The object was created in thread id 140094090184448 and this is thread id 140094168958784.\n",
      "\n",
      "During handling of the above exception, another exception occurred:\n",
      "\n",
      "Traceback (most recent call last):\n",
      "  File \"/opt/conda/lib/python3.8/site-packages/sqlalchemy/pool/base.py\", line 244, in _close_connection\n",
      "    self._dialect.do_close(connection)\n",
      "  File \"/opt/conda/lib/python3.8/site-packages/sqlalchemy/engine/default.py\", line 673, in do_close\n",
      "    dbapi_connection.close()\n",
      "sqlite3.ProgrammingError: SQLite objects created in a thread can only be used in that same thread. The object was created in thread id 140094090184448 and this is thread id 140094168958784.\n",
      "Traceback (most recent call last):\n",
      "  File \"run.py\", line 1, in <module>\n",
      "    from app.my_app import my_app\n",
      "ImportError: cannot import name 'my_app' from 'app.my_app' (/workspace/sample/app/my_app.py)\n"
     ]
    }
   ],
   "source": [
    "!python run.py"
   ]
  },
  {
   "cell_type": "code",
   "execution_count": null,
   "id": "b8f35ade-d11f-4895-a78f-3e80ef5b1dc4",
   "metadata": {},
   "outputs": [],
   "source": []
  }
 ],
 "metadata": {
  "kernelspec": {
   "display_name": "Python 3 (ipykernel)",
   "language": "python",
   "name": "python3"
  },
  "language_info": {
   "codemirror_mode": {
    "name": "ipython",
    "version": 3
   },
   "file_extension": ".py",
   "mimetype": "text/x-python",
   "name": "python",
   "nbconvert_exporter": "python",
   "pygments_lexer": "ipython3",
   "version": "3.8.3"
  }
 },
 "nbformat": 4,
 "nbformat_minor": 5
}
